<?xml version="1.0"?>
<robot name="myfirst">
 <link name="base_link">
  <visual>
   <geometry>
    <cylinder length="0.6" radius="0.25"/>
   </geometry>
  </visual>
  <collision>
   <geometry>
    <cylinder length="0.6" radius="0.25"/>
   </geometry>
  </collision>
 </link>
 <link name="sub_link">
  <visual>
   <geometry>
    <cylinder length="0.6" radius="0.25"/>
   </geometry>
  </visual>
  <collision>
   <geometry>
    <cylinder length="0.6" radius="0.25"/>
   </geometry>
  </collision>
 </link>
<joint name="base_to_sub" type="revolute">
<parent link="base_link"/>
<child link="sub_link"/>
<axis xyz="0 0 1"/>
<limit effort="10" upper="0" lower="10" velocity="1"/>
<origin rpy="0 0 0" xyz="0 0.5 0"/>
</joint>
</robot>