<?xml version="1.0"?>
<robot name="myfirst">
 <link name="base_link">
  <visual>
   <geometry>
    <box size="0.1 2 0.1"/>
   </geometry>
  </visual>
  <collision>
   <geometry>
    <box size="0.1 2 0.1"/>
   </geometry>
  </collision>
 </link>
 <link name="sub_link">
  <visual>
   <geometry>
    <sphere radius="0.2"/>   </geometry>
  </visual>
  <collision>
   <geometry>
    <sphere radius="0.2"/>   </geometry>
  </collision>
 </link>
<joint name="base_to_sub" type="revolute">
<parent link="base_link"/>
<child link="sub_link"/>
<axis xyz="0 1 0"/>
<limit effort="10" upper="0" lower="10" velocity="1"/>
<origin rpy="0 0 0" xyz="0 1 0"/>
</joint>
</robot>